<?xml version="1.0" encoding="UTF-8"?>
<!-- Generated by org.testng.reporters.JUnitReportReporter -->
<testsuite skipped="0" hostname="DESKTOP-TPKVVQE" name="Day22_DDT_2.datadriventesting.Assignment" tests="12" failures="1" timestamp="11 Jan 2023 17:51:51 GMT" time="62.077" errors="1">
  <testcase name="getData" time="1.188" classname="Day22_DDT_2.datadriventesting.Assignment"/>
  <testcase name="VtigerLogin" time="10.801" classname="Day22_DDT_2.datadriventesting.Assignment"/>
  <testcase name="cleanUp1" time="0.815" classname="Day22_DDT_2.datadriventesting.Assignment"/>
  <testcase name="getData1" time="0.297" classname="Day22_DDT_2.datadriventesting.Assignment"/>
  <testcase name="VtigerLogin1" time="6.997" classname="Day22_DDT_2.datadriventesting.Assignment">
    <failure type="java.lang.AssertionError" message="expected [vtiger] but found [Dashboard]">
      <![CDATA[java.lang.AssertionError: expected [vtiger] but found [Dashboard]
at org.testng.Assert.fail(Assert.java:96)
at org.testng.Assert.failNotEquals(Assert.java:776)
at org.testng.Assert.assertEqualsImpl(Assert.java:137)
at org.testng.Assert.assertEquals(Assert.java:118)
at org.testng.Assert.assertEquals(Assert.java:453)
at org.testng.Assert.assertEquals(Assert.java:463)
at Day22_DDT_2.datadriventesting.Assignment.VtigerLogin1(Assignment.java:72)
at sun.reflect.NativeMethodAccessorImpl.invoke0(Native Method)
at sun.reflect.NativeMethodAccessorImpl.invoke(NativeMethodAccessorImpl.java:62)
at sun.reflect.DelegatingMethodAccessorImpl.invoke(DelegatingMethodAccessorImpl.java:43)
at java.lang.reflect.Method.invoke(Method.java:498)
at org.testng.internal.MethodInvocationHelper.invokeMethod(MethodInvocationHelper.java:124)
at org.testng.internal.Invoker.invokeMethod(Invoker.java:583)
at org.testng.internal.Invoker.invokeTestMethod(Invoker.java:719)
at org.testng.internal.Invoker.invokeTestMethods(Invoker.java:989)
at org.testng.internal.TestMethodWorker.invokeTestMethods(TestMethodWorker.java:125)
at org.testng.internal.TestMethodWorker.run(TestMethodWorker.java:109)
at org.testng.TestRunner.privateRun(TestRunner.java:648)
at org.testng.TestRunner.run(TestRunner.java:505)
at org.testng.SuiteRunner.runTest(SuiteRunner.java:455)
at org.testng.SuiteRunner.runSequentially(SuiteRunner.java:450)
at org.testng.SuiteRunner.privateRun(SuiteRunner.java:415)
at org.testng.SuiteRunner.run(SuiteRunner.java:364)
at org.testng.SuiteRunnerWorker.runSuite(SuiteRunnerWorker.java:52)
at org.testng.SuiteRunnerWorker.run(SuiteRunnerWorker.java:84)
at org.testng.TestNG.runSuitesSequentially(TestNG.java:1208)
at org.testng.TestNG.runSuitesLocally(TestNG.java:1137)
at org.testng.TestNG.runSuites(TestNG.java:1049)
at org.testng.TestNG.run(TestNG.java:1017)
at org.testng.remote.AbstractRemoteTestNG.run(AbstractRemoteTestNG.java:115)
at org.testng.remote.RemoteTestNG.initAndRun(RemoteTestNG.java:251)
at org.testng.remote.RemoteTestNG.main(RemoteTestNG.java:77)
]]>
    </failure>
  </testcase> <!-- VtigerLogin1 -->
  <testcase name="cleanUp2" time="0.264" classname="Day22_DDT_2.datadriventesting.Assignment"/>
  <testcase name="getData2" time="0.234" classname="Day22_DDT_2.datadriventesting.Assignment"/>
  <testcase name="Acti_time" time="27.778" classname="Day22_DDT_2.datadriventesting.Assignment"/>
  <testcase name="cleanUp3" time="0.335" classname="Day22_DDT_2.datadriventesting.Assignment"/>
  <testcase name="getData3" time="0.132" classname="Day22_DDT_2.datadriventesting.Assignment">
    <error type="java.lang.RuntimeException" message="There is no support for this type of cell">
      <![CDATA[java.lang.RuntimeException: There is no support for this type of cell
at utilities.ExcelUtility.getCellValue(ExcelUtility.java:53)
at Day22_DDT_2.datadriventesting.Assignment.getData3(Assignment.java:113)
at sun.reflect.NativeMethodAccessorImpl.invoke0(Native Method)
at sun.reflect.NativeMethodAccessorImpl.invoke(NativeMethodAccessorImpl.java:62)
at sun.reflect.DelegatingMethodAccessorImpl.invoke(DelegatingMethodAccessorImpl.java:43)
at java.lang.reflect.Method.invoke(Method.java:498)
at org.testng.internal.MethodInvocationHelper.invokeMethod(MethodInvocationHelper.java:124)
at org.testng.internal.Invoker.invokeMethod(Invoker.java:583)
at org.testng.internal.Invoker.invokeTestMethod(Invoker.java:719)
at org.testng.internal.Invoker.invokeTestMethods(Invoker.java:989)
at org.testng.internal.TestMethodWorker.invokeTestMethods(TestMethodWorker.java:125)
at org.testng.internal.TestMethodWorker.run(TestMethodWorker.java:109)
at org.testng.TestRunner.privateRun(TestRunner.java:648)
at org.testng.TestRunner.run(TestRunner.java:505)
at org.testng.SuiteRunner.runTest(SuiteRunner.java:455)
at org.testng.SuiteRunner.runSequentially(SuiteRunner.java:450)
at org.testng.SuiteRunner.privateRun(SuiteRunner.java:415)
at org.testng.SuiteRunner.run(SuiteRunner.java:364)
at org.testng.SuiteRunnerWorker.runSuite(SuiteRunnerWorker.java:52)
at org.testng.SuiteRunnerWorker.run(SuiteRunnerWorker.java:84)
at org.testng.TestNG.runSuitesSequentially(TestNG.java:1208)
at org.testng.TestNG.runSuitesLocally(TestNG.java:1137)
at org.testng.TestNG.runSuites(TestNG.java:1049)
at org.testng.TestNG.run(TestNG.java:1017)
at org.testng.remote.AbstractRemoteTestNG.run(AbstractRemoteTestNG.java:115)
at org.testng.remote.RemoteTestNG.initAndRun(RemoteTestNG.java:251)
at org.testng.remote.RemoteTestNG.main(RemoteTestNG.java:77)
]]>
    </error>
  </testcase> <!-- getData3 -->
  <testcase name="Acti_time1" time="12.942" classname="Day22_DDT_2.datadriventesting.Assignment"/>
  <testcase name="cleanUp4" time="0.294" classname="Day22_DDT_2.datadriventesting.Assignment"/>
</testsuite> <!-- Day22_DDT_2.datadriventesting.Assignment -->
